Workbook

Sheet Selection
B2: Battery Parameter Selection
B4: Optimization Target | D4: Scope | E4: [-] | F4: Vehicle
D5: Target Function | E5: [-] | F5: Total Environmental Impact (distance-to-target)
B6: HDV Specifics | D6: Powertrain | E6: [-] | F6: BEV
D7: Vehicle Size | E7: [t] | F7: 40t
D8: Production Year | E8: [y] | F8: 2030
D9: Lifetime Milage | E9: [km] | F9: 1000000
D10: Driving Cycle | E10: [-] | F10: Long haul
D11: Target Range | E11: [km] | F11: 600
D12: Avg. Payload | E12: [kg] | F12: 15000
D13: Electricity Mix Production | E13: [-] | F13: Austria
D14: Electricity Mix Usage | E14: [-] | F14: Austria
D15: Hydro Power Share | E15: [%]
D16: Nuclear Share | E16: [%]
D17: Gas Share | E17: [%]
D18: Solar Share | E18: [%]
D19: Wind Share | E19: [%]
D20: Biomass Share | E20: [%]
D21: Coal Share | E21: [%]
D22: Oil Share | E22: [%]
D23: Geothermal Share | E23: [%]
D24: Waste Share | E24: [%]
D25: Biogas CCS Share | E25: [%]
D26: Biomass CCS Share | E26: [%]
... D35: Lignite Share | E35: [%]
B36: Battery Specifics | C36: System Level | D36: System Target Voltage | E36: [V] | F36: 830
D37: System Target Energy | E37: [kWh] | F37: 690
D38: System Target Power | E38: [kW] | F38: 450
D39: Volumentric Packing Efficiency | E39: [%] | F39: 0.88
D40: Replaceable Mounting: Added Mass | E40: [%] | F40: 0.05
D41: Number of Packs | E41: [#] | F41: 6 | I41: Coherence Check
D42: Available Volume per Pack | E42: [ccm] | F42: 100000000 | I42: specification sheets: | L42: calculation results:
C43: Pack Level | D43: Pack Target Voltage | E43: [V] | F43: 830 | I43: max pack dimensions:
D44: Pack Casing (Main) Material | E44: [-] | F44: Aluminium | I44: l | J44: 1812 | K44: mm
D45: Pack Casing Wall Thickness | E45: [mm] | F45: 5 | I45: h | J45: 620 | K45: mm
D46: Pack Cooling System Design | E46: [-] | F46: Glycol Cooling Plate | I46: w | J46: 382 | K46: mm
D47: Pack Cooling System Mass | E47: [kg/Pack] | F47: 33 | I47: v | J47: =J44*J45*J46/1000 -> 429154.08 | K47: cmm | L47: 429592
D48: Pack BMS Model | E48: [-] | F48: pack_bms_default | I48: pack energy | J48: 115 | K48: kWh | L48: =Parameters!I118*198/1000 -> 114.9984
D49: Pack Fuse Model | E49: [-] | F49: fuse_default | I49: pack capacity | J49: 162 | K49: Ah | L49: =Parameters!I117 -> 162
D50: Number of Fuses per Pack | E50: [#/Pack] | F50: 2 | I50: pack mass: | J50: 735.15 | K50: kg | L50: =4410.4/6 -> 735.06667
...

Sheet Input Optimization
B2: Battery Parameter Selection
B5: HDV Specifics | D5: Powertrain | E5: [-] | F5: =Selection!F6 -> BEV
D6: Vehicle Size | E6: [t] | F6: =Selection!F7 -> 40t
D7: Production Year | E7: [y] | F7: =Selection!F8 -> 2030
D8: Lifetime Milage | E8: [km] | F8: =Selection!F9 -> 1000000
D9: Driving Cycle | E9: [-] | F9: =Selection!F10 -> Long haul
D10: Target Range | E10: [km] | F10: =Selection!F11 -> 600
D11: Avg. Payload | E11: [kg] | F11: =Selection!F12 -> 15000
D12: Electricity Mix Production | E12: [-] | F12: =_xlfn.XLOOKUP(Selection!F13,Parameters!$M$6:$M$57,Parameters!$L$6:$L$57) -> AT
D13: Electricity Mix Usage | E13: [-] | F13: =_xlfn.XLOOKUP(Selection!F14,Parameters!$M$6:$M$57,Parameters!$L$6:$L$57) -> AT
B14: Battery Specifics | C14: System Level | D14: System Target Voltage | E14: [V] | F14: =Selection!F36 -> 830
D15: System Target Energy | E15: [kWh] | F15: =Selection!F37 -> 690
D16: System Target Power | E16: [kW] | F16: =Selection!F38 -> 450
D17: Volumentric Packing Efficiency | E17: [%] | F17: =Selection!F39 -> 0.88
D18: Replaceable Mounting: Added Mass | E18: [%] | F18: =Selection!F40+1 -> 1.05
C19: Pack Level | D19: Number of Packs | E19: [#] | F19: =Selection!F41 -> 6
D20: Available Volume per Pack | E20: [cm3] | F20: =Selection!F42 -> 100000000
D21: Pack Target Voltage | E21: [V] | F21: =Selection!F43 -> 830
D22: Pack Casing (Main) Material | E22: [-] | F22: =Selection!F44 -> Aluminium
D23: Pack Casing Wall Thicknss | E23: [mm] | F23: =Selection!F45 -> 5
D24: Pack Cooling System Design | E24: [-] | F24: =Selection!F46 -> Glycol Cooling Plate
D25: Pack Cooling System Mass | E25: [kg/Pack] | F25: =Selection!F47 -> 33
D26: Pack BMS Model | E26: [-] | F26: =Selection!F48 -> pack_bms_default
D27: Pack BMS Length | E27: [cm] | F27: =_xlfn.XLOOKUP(F$26,Parameters!$E$66:$N$66,Parameters!$E67:$N67) -> 15
D28: Pack BMS Width | E28: [cm] | F28: =_xlfn.XLOOKUP(F$26,Parameters!$E$66:$N$66,Parameters!$E68:$N68) -> 12
D29: Pack BMS Height | E29: [cm] | F29: =_xlfn.XLOOKUP(F$26,Parameters!$E$66:$N$66,Parameters!$E69:$N69) -> 3
D30: Pack BMS Mass | E30: [kg] | F30: =_xlfn.XLOOKUP(F$26,Parameters!$E$66:$N$66,Parameters!$E70:$N70) -> 0.4
D31: Pack Fuse Model | E31: [-] | F31: =Selection!F49 -> fuse_default
D32: Pack Fuse Length | E32: [cm] | F32: =_xlfn.XLOOKUP(F$31,Parameters!$E$78:$N$78,Parameters!$E79:$N79) -> 3
D33: Pack Fuse Width | E33: [cm] | F33: =_xlfn.XLOOKUP(F$31,Parameters!$E$78:$N$78,Parameters!$E80:$N80) -> 5
D34: Pack Fuse Height | E34: [cm] | F34: =_xlfn.XLOOKUP(F$31,Parameters!$E$78:$N$78,Parameters!$E81:$N81) -> 10
D35: Pack Fuse Mass | E35: [kg] | F35: =_xlfn.XLOOKUP(F$31,Parameters!$E$78:$N$78,Parameters!$E82:$N82) -> 0.15
D36: Number of Fuses per Pack | E36: [#/Pack] | F36: =Selection!F50 -> 2
D37: Pack Relay Model | E37: [-] | F37: =Selection!F51 -> relay_default
D38: Pack Relay Length | E38: [cm] | F38: =_xlfn.XLOOKUP(F$37,Parameters!$E$84:$N$84,Parameters!$E85:$N85) -> 5
D39: Pack Relay Width | E39: [cm] | F39: =_xlfn.XLOOKUP(F$37,Parameters!$E$84:$N$84,Parameters!$E86:$N86) -> 5
D40: Pack Relay Height | E40: [cm] | F40: =_xlfn.XLOOKUP(F$37,Parameters!$E$84:$N$84,Parameters!$E87:$N87) -> 10
D41: Pack Relay Mass | E41: [kg] | F41: =_xlfn.XLOOKUP(F$37,Parameters!$E$84:$N$84,Parameters!$E88:$N88) -> 0.1
D42: Number of Relays per Pack | E42: [#/Pack] | F42: =Selection!F52 -> 2
D43: Pack Current Sensor Model | E43: [-] | F43: =Selection!F53 -> current_sens_default
...

Sheet Absolute Thresholds
B2: Impact Category | C2: Abbreviation | D2: Unit | E2: Indicator in EF3.1 | F2: Planetary Boundary (global)*1 | G2: Unit | H2: Planetary Boundary per capita*2 | I2: Unit | J2: Planetary Boundary for Austria (equality allocation) *3 | K2: Unit | L2: Planetary Boundary for HDVs in Austria (grandfathering allocation) *4 | M2: Unit | N2: Planetary Boundary for HDV Tonnekilometers in Austria (based on demand expectations) *5 | O2: Unit
B3: climate change | C3: CC | D3: kg CO2 eq | E3: GWP100 | F3: 6800000000000 | G3: =_xlfn.CONCAT(D3," / globally") -> kg CO2 eq / globally | H3: =F3/C$21 -> 827.25061 | I3: =_xlfn.CONCAT(D3, " / per capita") -> kg CO2 eq / per capita | J3: =H3*C$22 -> 7.536253e+09 | K3: =_xlfn.CONCAT(D3, " / Austria") -> kg CO2 eq / Austria | L3: =J3*C$23 -> 5.4261022e+09 | M3: =_xlfn.CONCAT(D3, " / HDV in Austria") -> kg CO2 eq / HDV in Austria | N3: =L3/C$24 -> 9.8477354e-05 | O3: =_xlfn.CONCAT(D3, " / tkm (of HDV in Austria)") -> kg CO2 eq / tkm (of HDV in Austria)
B4: ozone depletion | C4: OD | D4: kg CFC11 eq | E4: Ozone depletion potential | F4: 593000000 | G4: =_xlfn.CONCAT(D4," / globally") -> kg CFC11 eq / globally | H4: =F4/C$21 -> 0.072141119 | I4: =_xlfn.CONCAT(D4, " / per capita") -> kg CFC11 eq / per capita | J4: =H4*C$22 -> 657205.6 | K4: =_xlfn.CONCAT(D4, " / Austria") -> kg CFC11 eq / Austria | L4: =J4*C$23 -> 473188.03 | M4: =_xlfn.CONCAT(D4, " / HDV in Austria") -> kg CFC11 eq / HDV in Austria | N4: =L4/C$24 -> 8.5878045e-09 | O4: =_xlfn.CONCAT(D4, " / tkm (of HDV in Austria)") -> kg CFC11 eq / tkm (of HDV in Austria)
B5: eutrophication: marine | C5: MEU | D5: kg N eq | E5: Fraction of nutrients reaching marine end compartment (N) | F5: 201000000000 | G5: =_xlfn.CONCAT(D5," / globally") -> kg N eq / globally | H5: =F5/C$21 -> 24.452555 | I5: =_xlfn.CONCAT(D5, " / per capita") -> kg N eq / per capita | J5: =H5*C$22 -> 2.2276277e+08 | K5: =_xlfn.CONCAT(D5, " / Austria") -> kg N eq / Austria | L5: =J5*C$23 -> 1.603892e+08 | M5: =_xlfn.CONCAT(D5, " / HDV in Austria") -> kg N eq / HDV in Austria | N5: =L5/C$24 -> 2.9108747e-06 | O5: =_xlfn.CONCAT(D5, " / tkm (of HDV in Austria)") -> kg N eq / tkm (of HDV in Austria)
B6: eutrophication: freshwater | C6: FEU | D6: kg P eq | E6: Fraction of nutrients reaching freshwater end compartent (P) | F6: 5810000000 | G6: =_xlfn.CONCAT(D6," / globally") -> kg P eq / globally | H6: =F6/C$21 -> 0.70681265 | I6: =_xlfn.CONCAT(D6, " / per capita") -> kg P eq / per capita | J6: =H6*C$22 -> 6439063.3 | K6: =_xlfn.CONCAT(D6, " / Austria") -> kg P eq / Austria | L6: =J6*C$23 -> 4636125.5 | M6: =_xlfn.CONCAT(D6, " / HDV in Austria") -> kg P eq / HDV in Austria | N6: =L6/C$24 -> 8.414021e-08 | O6: =_xlfn.CONCAT(D6, " / tkm (of HDV in Austria)") -> kg P eq / tkm (of HDV in Austria)
B7: acidification: terrestrial | C7: TAC | D7: mol H+ eq | E7: Accumulated Exeedance (AE) | F7: 1000000000000 | G7: =_xlfn.CONCAT(D7," / globally") -> mol H+ eq / globally | H7: =F7/C$21 -> 121.6545 | I7: =_xlfn.CONCAT(D7, " / per capita") -> mol H+ eq / per capita | J7: =H7*C$22 -> 1.1082725e+09 | K7: =_xlfn.CONCAT(D7, " / Austria") -> mol H+ eq / Austria | L7: =J7*C$23 -> 7.979562e+08 | M7: =_xlfn.CONCAT(D7, " / HDV in Austria") -> mol H+ eq / HDV in Austria | N7: =L7/C$24 -> 1.4481964e-05 | O7: =_xlfn.CONCAT(D7, " / tkm (of HDV in Austria)") -> mol H+ eq / tkm (of HDV in Austria)
B8: land use | C8: LU | D8: kg soil loss | E8: Soil erosion | F8: 1270000000000 | G8: =_xlfn.CONCAT(D8," / globally") -> kg soil loss / globally | H8: =F8/C$21 -> 154.50122 | I8: =_xlfn.CONCAT(D8, " / per capita") -> kg soil loss / per capita | J8: =H8*C$22 -> 1.4075061e+09 | K8: =_xlfn.CONCAT(D8, " / Austria") -> kg soil loss / Austria | L8: =J8*C$23 -> 1.0134044e+09 | M8: =_xlfn.CONCAT(D8, " / HDV in Austria") -> kg soil loss / HDV in Austria | N8: =L8/C$24 -> 1.8392094e-05 | O8: =_xlfn.CONCAT(D8, " / tkm (of HDV in Austria)") -> kg soil loss / tkm (of HDV in Austria)
B9: water use | C9: WU | D9: m3 world eq | E9: User deprivation potential | F9: 182000000000000 | G9: =_xlfn.CONCAT(D9," / globally") -> m3 world eq / globally | H9: =F9/C$21 -> 22141.119 | I9: =_xlfn.CONCAT(D9, " / per capita") -> m3 world eq / per capita | J9: =H9*C$22 -> 2.017056e+11 | K9: =_xlfn.CONCAT(D9, " / Austria") -> m3 world eq / Austria | L9: =J9*C$23 -> 1.4522803e+11 | M9: =_xlfn.CONCAT(D9, " / HDV in Austria") -> m3 world eq / HDV in Austria | N9: =L9/C$24 -> 0.0026357174 | O9: =_xlfn.CONCAT(D9, " / tkm (of HDV in Austria)") -> m3 world eq / tkm (of HDV in Austria)
B10: photochemical oxidant formation: human health | C10: POF | D10: kg NMVOC eq | E10: Tropospheric ozone concentration | F10: 407000000000 | G10: =_xlfn.CONCAT(D10," / globally") -> kg NMVOC eq / globally | H10: =F10/C$21 -> 49.513382 | I10: =_xlfn.CONCAT(D10, " / per capita") -> kg NMVOC eq / per capita | J10: =H10*C$22 -> 4.5106691e+08 | K10: =_xlfn.CONCAT(D10, " / Austria") -> kg NMVOC eq / Austria | L10: =J10*C$23 -> 3.2476818e+08 | M10: =_xlfn.CONCAT(D10, " / HDV in Austria") -> kg NMVOC eq / HDV in Austria | N10: =L10/C$24 -> 5.8941593e-06 | O10: =_xlfn.CONCAT(D10, " / tkm (of HDV in Austria)") -> kg NMVOC eq / tkm (of HDV in Austria)
B11: human toxicity: carcinogenic | C11: CHT | D11: CTUh | E11: Comparative toxic unit for humans | F11: 962000 | G11: =_xlfn.CONCAT(D11," / globally") -> CTUh / globally | H11: =F11/C$21 -> 0.00011703163 | I11: =_xlfn.CONCAT(D11, " / per capita") -> CTUh / per capita | J11: =H11*C$22 -> 1066.1582 | K11: =_xlfn.CONCAT(D11, " / Austria") -> CTUh / Austria | L11: =J11*C$23 -> 767.63387 | M11: =_xlfn.CONCAT(D11, " / HDV in Austria") -> CTUh / HDV in Austria | N11: =L11/C$24 -> 1.3931649e-11 | O11: =_xlfn.CONCAT(D11, " / tkm (of HDV in Austria)") -> CTUh / tkm (of HDV in Austria)
B12: human toxicity: non-carcinogenic | C12: NHT | D12: CTUh | E12: Comparative toxic unit for humans | F12: 4100000 | G12: =_xlfn.CONCAT(D12," / globally") -> CTUh / globally | H12: =F12/C$21 -> 0.00049878345 | I12: =_xlfn.CONCAT(D12, " / per capita") -> CTUh / per capita | J12: =H12*C$22 -> 4543.9173 | K12: =_xlfn.CONCAT(D12, " / Austria") -> CTUh / Austria | L12: =J12*C$23 -> 3271.6204 | M12: =_xlfn.CONCAT(D12, " / HDV in Austria") -> CTUh / HDV in Austria | N12: =L12/C$24 -> 5.9376052e-11 | O12: =_xlfn.CONCAT(D12, " / tkm (of HDV in Austria)") -> CTUh / tkm (of HDV in Austria)
B13: ecotoxicity: freshwater | C13: FET | D13: CTUe | E13: Comparative toxic unit for ecosystems | F13: 131000000000000 | G13: =_xlfn.CONCAT(D13," / globally") -> CTUe / globally | H13: =F13/C$21 -> 15936.74 | I13: =_xlfn.CONCAT(D13, " / per capita") -> CTUe / per capita | J13: =H13*C$22 -> 1.451837e+11 | K13: =_xlfn.CONCAT(D13, " / Austria") -> CTUe / Austria | L13: =J13*C$23 -> 1.0453226e+11 | M13: =_xlfn.CONCAT(D13, " / HDV in Austria") -> CTUe / HDV in Austria | N13: =L13/C$24 -> 0.0018971373 | O13: =_xlfn.CONCAT(D13, " / tkm (of HDV in Austria)") -> CTUe / tkm (of HDV in Austria)
B14: ionising radiation | C14: IR | D14: kBq U235 eq | E14: Human exposure efficiency relative to U235 | F14: 527000000000000 | G14: =_xlfn.CONCAT(D14," / globally") -> kBq U235 eq / globally | H14: =F14/C$21 -> 64111.922 | I14: =_xlfn.CONCAT(D14, " / per capita") -> kBq U235 eq / per capita | J14: =H14*C$22 -> 5.8405961e+11 | K14: =_xlfn.CONCAT(D14, " / Austria") -> kBq U235 eq / Austria | L14: =J14*C$23 -> 4.2052292e+11 | M14: =_xlfn.CONCAT(D14, " / HDV in Austria") -> kBq U235 eq / HDV in Austria | N14: =L14/C$24 -> 0.0076319949 | O14: =_xlfn.CONCAT(D14, " / tkm (of HDV in Austria)") -> kBq U235 eq / tkm (of HDV in Austria)
... B16: material resources: metals/minerals | C16: MR | D16: kg Sb eq | E16: Abiotic resource depletion - ultimate reserves | F16: 219000000 | G16: =_xlfn.CONCAT(D16," / globally") -> kg Sb eq / globally | H16: =F16/C$21 -> 0.026642336 | I16: =_xlfn.CONCAT(D16, " / per capita") -> kg Sb eq / per capita | J16: =H16*C$22 -> 242711.68 | K16: =_xlfn.CONCAT(D16, " / Austria") -> kg Sb eq / Austria | L16: =J16*C$23 -> 174752.41 | M16: =_xlfn.CONCAT(D16, " / HDV in Austria") -> kg Sb eq / HDV in Austria | N16: =L16/C$24 -> 3.1715501e-09 | O16: =_xlfn.CONCAT(D16, " / tkm (of HDV in Austria)") -> kg Sb eq / tkm (of HDV in Austria)
C19: Value | D19: Unit | E19: Reference
B20: *1 | C20: - | D20: - | E20: Sala et al., 2020. Environmental sustainability of European production and consumption assessed against planetary boundaries. Journal of Environmental Management, 269:110686. https://doi.org/10.1016/j.jenvman.2020.110686
B21: *2 | C21: 8220000000 | D21: world population (2025) | E21: Worldometers (2025), https://www.worldometers.info/world-population/ (accessed: 10th April 2025)
B22: *3 | C22: 9110000 | D22: population Austria (2025) | E22: Worldometers (2025), https://www.worldometers.info/world-population/ (accessed: 10th April 2025)
B23: *4 | C23: 0.72 | D23: transportation share via road in Austria | E23: Statistic Austria 2023, https://www.statistik.at/statistiken/tourismus-und-verkehr/gueterverkehr/modal-split (accessed: 10th April 2025)
B24: *5 | C24: 55100000000000 | D24: transport volume via road in Austria 2023 (linear trend) | E24: Statistic Austria 2023, https://www.statistik.at/statistiken/tourismus-und-verkehr/gueterverkehr/gueterverkehr-strasse/gueterverkehr-auf-oesterreichs-strassen (accessed: 10th April 2025)

Sheet Parameters
B2: Design Options and Ranges
B3: HDV Specifics | O3: Battery Specifics
B4: Powertrain | C4: Vehicle Size | D4: Production Year | E4: Lifetime Milage | F4: Driving Cycle | G4: Target Range | H4: Avg. Payload | I4: Electricity Mix of Production | J4: Electricity Mix of Use | K4: (Electricity Carrier) | O4: System Target Voltage | P4: System Target Energy | Q4: System Target Power | R4: Number of Packs | S4: Available Volume per Pack | T4: Pack Target Voltage | U4: Pack Casing Material (mix) | V4: Pack Casing Wall Thickness | W4: Pack Cooling System Design | Y4: Number of Fuses on Pack-Level | Z4: Number of Relays on Pack-Level | AA4: Number of Current Sensors on Pack-Level | AB4: Number of Voltage Sensors on Pack-Level | AC4: Number of Temperature Sensors on Pack-Level | AD4: Module Casing Material (mix) | AE4: Module Casing Design | AF4: Number of Current Sensors on Module-Level | AG4: Voltage Sensors per parallel line | AH4: Number of Temperature Sensors on Module-Level | AJ4: Optimization Target | AK4: Impact Thresholds | AM4: Optimzation Scope
B5: [-] | C5: [t] | D5: [y] | E5: [km] | F5: [-] | G5: [km] | H5: [kg] | I5: [%] | J5: [%] | K5: [-] | O5: [V] | P5: [kWh] | Q5: [kW] | R5: [#] | S5: [cm3] | T5: [V] | U5: [-] | V5: [mm] | W5: [-] | X5: [kg/Pack] | Y5: [#/Pack] | Z5: [#/Pack] | AA5: [#/Pack] | AB5: [#/Pack] | AC5: [#/Pack] | AD5: [-] | AE5: [-] | AF5: [#/Module] | AG5: [-] | AH5: [#/Module] | AJ5: [-] | AM5: [-]
B6: BEV | C6: 7.5t | D6: 2020 | E6: 100000 | F6: Urban delivery | G6: 50 | H6: 1000 | K6: Hydro | L6: AU | M6: Australia | O6: 200 | P6: 60 | Q6: 100 | R6: 1 | S6: 100000 | T6: 50 | U6: Steel | V6: 0.5 | W6: Ventilation | X6: 1 | Y6: 1 | Z6: 1 | AA6: 0 | AB6: 0 | AC6: 0 | AD6: Aluminium | AE6: Open (no filling) | AF6: 0 | AG6: Yes | AH6: 0 | AJ6: ='Absolute Thresholds'!B3 -> climate change | AK6: ='Absolute Thresholds'!N3 -> 9.8477354e-05 | AL6: ='Absolute Thresholds'!O3 -> kg CO2 eq / tkm (of HDV in Austria) | AM6: Vehicle
B7: PHEV-d | C7: 12t | D7: 2050 | E7: 2000000 | F7: Regional delivery | G7: 800 | H7: 20000 | K7: Nuclear | L7: AT | M7: Austria | O7: 1000 | P7: 1000 | Q7: 600 | R7: 10 | S7: 100000000 | T7: 1000 | U7: Aluminium | V7: 10 | W7: Glycol Cooling Plate | X7: 50 | Y7: 4 | Z7: 4 | AA7: 4 | AB7: 4 | AC7: 4 | AD7: Plastics | AE7: Open (foam filling) | AF7: 1 | AG7: No | AH7: 5 | AJ7: ='Absolute Thresholds'!B4 -> ozone depletion | AK7: ='Absolute Thresholds'!N4 -> 8.5878045e-09 | AL7: ='Absolute Thresholds'!O4 -> kg CFC11 eq / tkm (of HDV in Austria) | AM7: Battery
B8: FCEV | C8: 18t | F8: Long haul | K8: Gas | L8: BE | M8: Belgium | U8: Plastics | W8: Liquid Metal Cooling Plate | AD8: Aluminium/Plastics | AE8: Closed (no filling; not sealed) | AJ8: ='Absolute Thresholds'!B5 -> eutrophication: marine | AK8: ='Absolute Thresholds'!N5 -> 2.9108747e-06 | AL8: ='Absolute Thresholds'!O5 -> kg N eq / tkm (of HDV in Austria)
C9: 26t | K9: Solar | L9: BA | M9: Bosnia and Herzegovina | AE9: Closed (foam filling; not sealed) | AJ9: ='Absolute Thresholds'!B6 -> eutrophication: freshwater | AK9: ='Absolute Thresholds'!N6 -> 8.414021e-08 | AL9: ='Absolute Thresholds'!O6 -> kg P eq / tkm (of HDV in Austria)
C10: 32t | K10: Wind | L10: BR | M10: Brazil | AE10: Closed (no filling; sealed) | AJ10: ='Absolute Thresholds'!B7 -> acidification: terrestrial | AK10: ='Absolute Thresholds'!N7 -> 1.4481964e-05 | AL10: ='Absolute Thresholds'!O7 -> mol H+ eq / tkm (of HDV in Austria)
C11: 40t | K11: Biomass | L11: BG | M11: Bulgaria | AE11: Closed (foam filling; sealed) | AJ11: ='Absolute Thresholds'!B8 -> land use | AK11: ='Absolute Thresholds'!N8 -> 1.8392094e-05 | AL11: ='Absolute Thresholds'!O8 -> kg soil loss / tkm (of HDV in Austria)
C12: 60t | K12: Coal | L12: CA | M12: Canada | AJ12: ='Absolute Thresholds'!B9 -> water use | AK12: ='Absolute Thresholds'!N9 -> 0.0026357174 | AL12: ='Absolute Thresholds'!O9 -> m3 world eq / tkm (of HDV in Austria)
K13: Oil | L13: CL | M13: Chile | AJ13: ='Absolute Thresholds'!B10 -> photochemical oxidant formation: human health | AK13: ='Absolute Thresholds'!N10 -> 5.8941593e-06 | AL13: ='Absolute Thresholds'!O10 -> kg NMVOC eq / tkm (of HDV in Austria)
K14: Geothermal | L14: CN | M14: China | AJ14: ='Absolute Thresholds'!B11 -> human toxicity: carcinogenic | AK14: ='Absolute Thresholds'!N11 -> 1.3931649e-11 | AL14: ='Absolute Thresholds'!O11 -> CTUh / tkm (of HDV in Austria)
K15: Waste | L15: HR | M15: Crotia | AJ15: ='Absolute Thresholds'!B12 -> human toxicity: non-carcinogenic | AK15: ='Absolute Thresholds'!N12 -> 5.9376052e-11 | AL15: ='Absolute Thresholds'!O12 -> CTUh / tkm (of HDV in Austria)
K16: Biogas CCS | L16: CZ | M16: Czech Republic | AJ16: ='Absolute Thresholds'!B13 -> ecotoxicity: freshwater | AK16: ='Absolute Thresholds'!N13 -> 0.0018971373 | AL16: ='Absolute Thresholds'!O13 -> CTUe / tkm (of HDV in Austria)
K17: Biomass CCS | L17: DK | M17: Denmark | AJ17: ='Absolute Thresholds'!B14 -> ionising radiation | AK17: ='Absolute Thresholds'!N14 -> 0.0076319949 | AL17: ='Absolute Thresholds'!O14 -> kBq U235 eq / tkm (of HDV in Austria)
K18: Coal CCS | L18: EU | M18: European Union | AJ18: ='Absolute Thresholds'!B15 -> energy resources depletion: non-renewable | AK18: ='Absolute Thresholds'!N15 -> 0.00034756713 | AL18: ='Absolute Thresholds'!O15 -> MJ / tkm (of HDV in Austria)
K19: Gas CCS | L19: FI | M19: Finland | AJ19: ='Absolute Thresholds'!B16 -> material resources: metals/minerals | AK19: ='Absolute Thresholds'!N16 -> 3.1715501e-09 | AL19: ='Absolute Thresholds'!O16 -> kg Sb eq / tkm (of HDV in Austria)
K20: Wood CCS | L20: FR | M20: France | AJ20: Total Environmental Impact (distance-to-target)
K21: Hydro, reservoir | L21: DE | M21: Germany
K22: Gas CCGT | L22: GLO | M22: Global
K23: Gas CHP | L23: GR | M23: Greece
K24: Solar, thermal | L24: HU | M24: Hungary
K25: Wind, offshore | L25: IN | M25: India
K26: Lignite | L26: ID | M26: Indonesia
L27: IR | M27: Iran
L28: IE | M28: Ireland
L29: IT | M29: Italty
L30: JP | M30: Japan
L31: LU | M31: Luxembourg
L32: MK | M32: Macedonia
L33: MY | M33: Malaysia
L34: MX | M34: Mexico
L35: NL | M35: Netherland
L36: NO | M36: Norway
L37: PE | M37: Peru
L38: PL | M38: Poland
... L57: US | M57: United States
B66: BMS | C66: Fuse Type | D66: [-] | E66: pack_bms_default | F66: module_bms_default
C67: Fuse Length | D67: [cm] | E67: 15 | F67: 12
...
